Workbook

Sheet PG Summary
A1: Asterknight — Summary
A2: All values calculate from the Matches tab.
A3: Stat | B3: Value
A4: Games | B4: =COUNTA('PG Matches'!$D$5:$D$1000)
A5: Wins | B5: =COUNTIF('PG Matches'!$G$5:$G$1000,"W")
A6: Losses | B6: =COUNTIF('PG Matches'!$G$5:$G$1000,"L")
A7: Win rate | B7: =IF(B4=0,0,B5/B4)
A8: Total killing blows | B8: =SUM('PG Matches'!$J$5:$J$1000)
A9: Total player0354 kills | B9: =SUM('PG Matches'!$K$5:$K$1000)
A10: Total damage (M) | B10: =SUM('PG Matches'!$M$5:$M$1000)
A11: Total healing (M) | B11: =SUM('PG Matches'!$N$5:$N$1000)
A12: Avg killing blows | B12: =AVERAGE('PG Matches'!$J$5:$J$1000)
A13: Avg player0354 kills | B13: =AVERAGE('PG Matches'!$K$5:$K$1000)
A14: Avg damage per game (M) | B14: =AVERAGE('PG Matches'!$M$5:$M$1000)
A15: Avg healing per game (M) | B15: =AVERAGE('PG Matches'!$N$5:$N$1000)
A16: Damage per minute (M), games with duration | B16: =SUMIFS('PG Matches'!$M$5:$M$1000,'PG Matches'!$F$5:$F$1000,">0")/(SUM('PG Matches'!$F$5:$F$1000)*1440)
A17: Best damage (M) | B17: =MAX('PG Matches'!$M$5:$M$1000)
A18: Best killing blows | B18: =MAX('PG Matches'!$J$5:$J$1000)
A19: Best player0354 kills | B19: =MAX('PG Matches'!$K$5:$K$1000)
A20: Games with deaths tracked | B20: =COUNT('PG Matches'!$L$5:$L$1000)
A21: Avg deaths (tracked games) | B21: =IF(B20=0,"",AVERAGE('PG Matches'!$L$5:$L$1000))
A22: Total honor | B22: =SUM('PG Matches'!$P$5:$P$1000)
A25: By map type
A26: Map type | B26: Games | C26: Wins | D26: Win rate | E26: Avg damage (M) | F26: Damage / min (M) | G26: Avg HKs
A27: Bases | B27: =COUNTIF('PG Matches'!$E$5:$E$1000,A27) | C27: =COUNTIFS('PG Matches'!$E$5:$E$1000,A27,'PG Matches'!$G$5:$G$1000,"W") | D27: =IF(B27=0,"",C27/B27) | E27: =IF(B27=0,"",SUMIFS('PG Matches'!$M$5:$M$1000,'PG Matches'!$E$5:$E$1000,A27)/B27) | F27: =IF(SUMIFS('PG Matches'!$F$5:$F$1000,'PG Matches'!$E$5:$E$1000,A27)=0,"",SUMIFS('PG Matches'!$M$5:$M$1000,'PG Matches'!$E$5:$E$1000,A27,'PG Matches'!$F$5:$F$1000,">0")/(SUMIFS('PG Matches'!$F$5:$F$1000,'PG Matches'!$E$5:$E$1000,A27)*1440)) | G27: =IF(B27=0,"",SUMIFS('PG Matches'!$K$5:$K$1000,'PG Matches'!$E$5:$E$1000,A27)/B27)
A28: Flag | B28: =COUNTIF('PG Matches'!$E$5:$E$1000,A28) | C28: =COUNTIFS('PG Matches'!$E$5:$E$1000,A28,'PG Matches'!$G$5:$G$1000,"W") | D28: =IF(B28=0,"",C28/B28) | E28: =IF(B28=0,"",SUMIFS('PG Matches'!$M$5:$M$1000,'PG Matches'!$E$5:$E$1000,A28)/B28) | F28: =IF(SUMIFS('PG Matches'!$F$5:$F$1000,'PG Matches'!$E$5:$E$1000,A28)=0,"",SUMIFS('PG Matches'!$M$5:$M$1000,'PG Matches'!$E$5:$E$1000,A28,'PG Matches'!$F$5:$F$1000,">0")/(SUMIFS('PG Matches'!$F$5:$F$1000,'PG Matches'!$E$5:$E$1000,A28)*1440)) | G28: =IF(B28=0,"",SUMIFS('PG Matches'!$K$5:$K$1000,'PG Matches'!$E$5:$E$1000,A28)/B28)
A29: Flag + Bases | B29: =COUNTIF('PG Matches'!$E$5:$E$1000,A29) | C29: =COUNTIFS('PG Matches'!$E$5:$E$1000,A29,'PG Matches'!$G$5:$G$1000,"W") | D29: =IF(B29=0,"",C29/B29) | E29: =IF(B29=0,"",SUMIFS('PG Matches'!$M$5:$M$1000,'PG Matches'!$E$5:$E$1000,A29)/B29) | F29: =IF(SUMIFS('PG Matches'!$F$5:$F$1000,'PG Matches'!$E$5:$E$1000,A29)=0,"",SUMIFS('PG Matches'!$M$5:$M$1000,'PG Matches'!$E$5:$E$1000,A29,'PG Matches'!$F$5:$F$1000,">0")/(SUMIFS('PG Matches'!$F$5:$F$1000,'PG Matches'!$E$5:$E$1000,A29)*1440)) | G29: =IF(B29=0,"",SUMIFS('PG Matches'!$K$5:$K$1000,'PG Matches'!$E$5:$E$1000,A29)/B29)
A30: Orbs | B30: =COUNTIF('PG Matches'!$E$5:$E$1000,A30) | C30: =COUNTIFS('PG Matches'!$E$5:$E$1000,A30,'PG Matches'!$G$5:$G$1000,"W") | D30: =IF(B30=0,"",C30/B30) | E30: =IF(B30=0,"",SUMIFS('PG Matches'!$M$5:$M$1000,'PG Matches'!$E$5:$E$1000,A30)/B30) | F30: =IF(SUMIFS('PG Matches'!$F$5:$F$1000,'PG Matches'!$E$5:$E$1000,A30)=0,"",SUMIFS('PG Matches'!$M$5:$M$1000,'PG Matches'!$E$5:$E$1000,A30,'PG Matches'!$F$5:$F$1000,">0")/(SUMIFS('PG Matches'!$F$5:$F$1000,'PG Matches'!$E$5:$E$1000,A30)*1440)) | G30: =IF(B30=0,"",SUMIFS('PG Matches'!$K$5:$K$1000,'PG Matches'!$E$5:$E$1000,A30)/B30)
A31: Carts | B31: =COUNTIF('PG Matches'!$E$5:$E$1000,A31) | C31: =COUNTIFS('PG Matches'!$E$5:$E$1000,A31,'PG Matches'!$G$5:$G$1000,"W") | D31: =IF(B31=0,"",C31/B31) | E31: =IF(B31=0,"",SUMIFS('PG Matches'!$M$5:$M$1000,'PG Matches'!$E$5:$E$1000,A31)/B31) | F31: =IF(SUMIFS('PG Matches'!$F$5:$F$1000,'PG Matches'!$E$5:$E$1000,A31)=0,"",SUMIFS('PG Matches'!$M$5:$M$1000,'PG Matches'!$E$5:$E$1000,A31,'PG Matches'!$F$5:$F$1000,">0")/(SUMIFS('PG Matches'!$F$5:$F$1000,'PG Matches'!$E$5:$E$1000,A31)*1440)) | G31: =IF(B31=0,"",SUMIFS('PG Matches'!$K$5:$K$1000,'PG Matches'!$E$5:$E$1000,A31)/B31)
A32: Azerite | B32: =COUNTIF('PG Matches'!$E$5:$E$1000,A32) | C32: =COUNTIFS('PG Matches'!$E$5:$E$1000,A32,'PG Matches'!$G$5:$G$1000,"W") | D32: =IF(B32=0,"",C32/B32) | E32: =IF(B32=0,"",SUMIFS('PG Matches'!$M$5:$M$1000,'PG Matches'!$E$5:$E$1000,A32)/B32) | F32: =IF(SUMIFS('PG Matches'!$F$5:$F$1000,'PG Matches'!$E$5:$E$1000,A32)=0,"",SUMIFS('PG Matches'!$M$5:$M$1000,'PG Matches'!$E$5:$E$1000,A32,'PG Matches'!$F$5:$F$1000,">0")/(SUMIFS('PG Matches'!$F$5:$F$1000,'PG Matches'!$E$5:$E$1000,A32)*1440)) | G32: =IF(B32=0,"",SUMIFS('PG Matches'!$K$5:$K$1000,'PG Matches'!$E$5:$E$1000,A32)/B32)
A33: Epic | B33: =COUNTIF('PG Matches'!$E$5:$E$1000,A33) | C33: =COUNTIFS('PG Matches'!$E$5:$E$1000,A33,'PG Matches'!$G$5:$G$1000,"W") | D33: =IF(B33=0,"",C33/B33) | E33: =IF(B33=0,"",SUMIFS('PG Matches'!$M$5:$M$1000,'PG Matches'!$E$5:$E$1000,A33)/B33) | F33: =IF(SUMIFS('PG Matches'!$F$5:$F$1000,'PG Matches'!$E$5:$E$1000,A33)=0,"",SUMIFS('PG Matches'!$M$5:$M$1000,'PG Matches'!$E$5:$E$1000,A33,'PG Matches'!$F$5:$F$1000,">0")/(SUMIFS('PG Matches'!$F$5:$F$1000,'PG Matches'!$E$5:$E$1000,A33)*1440)) | G33: =IF(B33=0,"",SUMIFS('PG Matches'!$K$5:$K$1000,'PG Matches'!$E$5:$E$1000,A33)/B33)

Sheet PG Matches
A1: Asterknight — Battleground Match Log
A2: Blue = entered data · Black = formulas · Green rows = wins, red rows = losses. See the Guide tab to add matches.
A4: Game # | B4: Date | C4: Time | D4: Battleground | E4: Map type | F4: Duration | G4: Result | H4: Our score | I4: Enemy score | J4: KB | K4: HK | L4: Deaths | M4: Damage (M) | N4: Healing (M) | O4: Damage / min (M) | P4: Honor | Q4: Conquest | R4: Role | S4: Bases assaulted | T4: Bases defended | U4: Flag captures | V4: Flag returns | W4: Carts controlled | X4: Orb possessions | Y4: Victory points | Z4: Top Horde damage (M) | AA4: Damage share | AB4: Data source | AC4: Notes | AD4: Horde deaths | AE4: Alliance deaths | AF4: Healers (Horde vs Alliance) | AG4: Horde healing (M) | AH4: Alliance healing (M) | AI4: Premade on mains? | AJ4: Teammates on mains
A5: 1 | B5: 47772 | C5: 10:59 AM | D5: The Battle for Gilneas | E5: Bases | F5: 0.0097222222 | G5: L | J5: 7 | K5: 1 | M5: 4.226227 | N5: 1.286207 | O5: =IF(OR(F5="",F5=0),"",M5/(F5*1440)) | P5: 430 | AA5: =IF(Z5="","",M5/Z5) | AB5: REFlex
A6: 2 | B6: 47772 | C6: 08:01 PM | D6: Silvershard Mines | E6: Carts | F6: 0.0048611111 | G6: W | J6: 4 | K6: 1 | M6: 13.734027 | N6: 7.571767 | O6: =IF(OR(F6="",F6=0),"",M6/(F6*1440)) | P6: 755 | AA6: =IF(Z6="","",M6/Z6) | AB6: REFlex
A7: 3 | B7: 47773 | C7: 09:13 AM | D7: The Battle for Gilneas | E7: Bases | F7: 0.0074652778 | G7: L | J7: 7 | K7: 10 | M7: 24.228227 | N7: 12.147567 | O7: =IF(OR(F7="",F7=0),"",M7/(F7*1440)) | P7: 513 | AA7: =IF(Z7="","",M7/Z7) | AB7: REFlex
A8: 4 | B8: 47773 | C8: 09:51 AM | D8: Eye of the Storm | E8: Flag + Bases | F8: 0.004525463 | G8: L | J8: 0 | K8: 9 | M8: 11.816027 | N8: 11.133767 | O8: =IF(OR(F8="",F8=0),"",M8/(F8*1440)) | P8: 322 | AA8: =IF(Z8="","",M8/Z8) | AB8: REFlex
A9: 5 | B9: 47773 | C9: 10:09 AM | D9: Eye of the Storm | E9: Flag + Bases | F9: 0.0097453704 | G9: W | J9: 0 | K9: 9 | M9: 20.940227 | N9: 14.010767 | O9: =IF(OR(F9="",F9=0),"",M9/(F9*1440)) | P9: 1541 | AA9: =IF(Z9="","",M9/Z9) | AB9: REFlex | AC9: Synthetic example
A10: 6 | B10: 47773 | C10: 10:24 AM | D10: Deephaul Ravine | E10: Carts | F10: 0.0075347222 | G10: W | J10: 0 | K10: 2 | M10: 28.256027 | N10: 19.901767 | O10: =IF(OR(F10="",F10=0),"",M10/(F10*1440)) | P10: 1205 | AA10: =IF(Z10="","",M10/Z10) | AB10: REFlex
A11: 7 | B11: 47773 | C11: 10:43 AM | D11: Silvershard Mines | E11: Carts | F11: 0.0049768519 | G11: L | J11: 0 | K11: 0 | M11: 10.226827 | N11: 10.366567 | O11: =IF(OR(F11="",F11=0),"",M11/(F11*1440)) | P11: 363 | AA11: =IF(Z11="","",M11/Z11) | AB11: REFlex | AC11: Synthetic example
A12: 8 | B12: 47773 | C12: 11:04 AM | D12: Eye of the Storm | E12: Flag + Bases | F12: 0.011886574 | G12: L | J12: 10 | K12: 8 | M12: 40.586027 | N12: 18.613967 | O12: =IF(OR(F12="",F12=0),"",M12/(F12*1440)) | P12: 756 | AA12: =IF(Z12="","",M12/Z12) | AB12: REFlex | AC12: Synthetic example
A13: 9 | B13: 47773 | C13: 04:54 PM | D13: The Battle for Gilneas | E13: Bases | F13: 0.0076967593 | G13: W | J13: 7 | K13: 4 | M13: 27.105227 | N13: 12.969567 | O13: =IF(OR(F13="",F13=0),"",M13/(F13*1440)) | P13: 1093 | AA13: =IF(Z13="","",M13/Z13) | AB13: REFlex
A14: 10 | B14: 47773 | C14: 05:09 PM | D14: Silvershard Mines | E14: Carts | F14: 0.0064351852 | G14: L | H14: 1049 | I14: 1517 | J14: 2 | K14: 2 | L14: 2 | M14: 11.870827 | N14: 12.065367 | O14: =IF(OR(F14="",F14=0),"",M14/(F14*1440)) | P14: 594 | Q14: 0 | R14: Team fights | W14: 20 | Z14: 33 | AA14: =IF(Z14="","",M14/Z14) | AB14: REFlex + scoreboard | AC14: Synthetic example | AI14: Yes | AJ14: 2 of 3 (visible roster)
A15: 11 | B15: 47773 | C15: 05:24 PM | D15: The Battle for Gilneas | E15: Bases | F15: 0.0043287037 | G15: W | J15: 4 | K15: 8 | M15: 6.363427 | N15: 3.598767 | O15: =IF(OR(F15="",F15=0),"",M15/(F15*1440)) | P15: 1047 | AA15: =IF(Z15="","",M15/Z15) | AB15: REFlex
A16: 12 | B16: 47773 | C16: 05:51 PM | D16: Arathi Basin | E16: Bases | F16: 0.008900463 | G16: W | J16: 7 | K16: 10 | M16: 17.789227 | N16: 13.736767 | O16: =IF(OR(F16="",F16=0),"",M16/(F16*1440)) | P16: 950 | AA16: =IF(Z16="","",M16/Z16) | AB16: REFlex
A17: 13 | B17: 47773 | C17: 06:11 PM | D17: Seething Shore | E17: Azerite | F17: 0.0077314815 | G17: L | J17: 0 | K17: 0 | M17: 36.722627 | N17: 16.010967 | O17: =IF(OR(F17="",F17=0),"",M17/(F17*1440)) | P17: 322 | AA17: =IF(Z17="","",M17/Z17) | AB17: REFlex
A18: 14 | B18: 47773 | C18: 06:33 PM | D18: Arathi Basin | E18: Bases | F18: 0.0092013889 | G18: L | H18: 841 | I18: 1517 | J18: 4 | K18: 1 | L18: 4 | M18: 25.981827 | N18: 18.860567 | O18: =IF(OR(F18="",F18=0),"",M18/(F18*1440)) | P18: 373 | Q18: 0 | R18: Base defense | S18: 0 | T18: 0 | Z18: 58 | AA18: =IF(Z18="","",M18/Z18) | AB18: REFlex + scoreboard | AC18: Synthetic example | AI18: No | AJ18: 1 of 1 (visible roster)
A19: 15 | B19: 47773 | C19: 06:54 PM | D19: Deepwind Gorge | E19: Bases | F19: 0.0091203704 | G19: L | H19: 900 | I19: 1517 | J19: 0 | K19: 6 | L19: 5 | M19: 24.940627 | N19: 10.476167 | O19: =IF(OR(F19="",F19=0),"",M19/(F19*1440)) | P19: 344 | Q19: 0 | R19: Base defense | S19: 18 | T19: 0 | Z19: 35 | AA19: =IF(Z19="","",M19/Z19) | AB19: REFlex + scoreboard | AC19: Synthetic example | AI19: No | AJ19: 1 of 1 (visible roster)
A20: 16 | B20: 47773 | C20: 07:09 PM | D20: Twin Peaks | E20: Flag | F20: 0.0071990741 | G20: W | H20: 20 | I20: 0 | J20: 0 | K20: 3 | L20: 4 | M20: 14.008027 | N20: 11.270767 | O20: =IF(OR(F20="",F20=0),"",M20/(F20*1440)) | P20: 704 | Q20: 35 | R20: Flag carrier | U20: 19 | V20: 0 | Z20: 44 | AA20: =IF(Z20="","",M20/Z20) | AB20: REFlex + scoreboard | AC20: Synthetic example | AI20: No | AJ20: 1 of 1 (visible roster)
A21: 17 | B21: 47773 | C21: 07:27 PM | D21: Deephaul Ravine | E21: Carts | F21: 0.0058101852 | G21: L | J21: 10 | K21: 4 | M21: 24.694027 | N21: 8.832167 | O21: =IF(OR(F21="",F21=0),"",M21/(F21*1440)) | P21: 211 | AA21: =IF(Z21="","",M21/Z21) | AB21: REFlex
A22: 18 | B22: 47774 | C22: 09:17 AM | D22: Deephaul Ravine | E22: Carts | F22: 0.005150463 | G22: W | J22: 10 | K22: 0 | M22: 29.324627 | N22: 7.900567 | O22: =IF(OR(F22="",F22=0),"",M22/(F22*1440)) | P22: 1024 | AA22: =IF(Z22="","",M22/Z22) | AB22: REFlex
A23: 19 | B23: 47774 | C23: 09:38 AM | D23: Eye of the Storm | E23: Flag + Bases | F23: 0.0077199074 | G23: L | J23: 4 | K23: 1 | M23: 27.488827 | N23: 18.833167 | O23: =IF(OR(F23="",F23=0),"",M23/(F23*1440)) | P23: 242 | AA23: =IF(Z23="","",M23/Z23) | AB23: REFlex | AC23: Synthetic example
A24: 20 | B24: 47774 | C24: 09:52 AM | D24: Eye of the Storm | E24: Flag + Bases | F24: 0.0071643519 | G24: L | J24: 7 | K24: 0 | M24: 22.063627 | N24: 18.997567 | O24: =IF(OR(F24="",F24=0),"",M24/(F24*1440)) | P24: 285 | AA24: =IF(Z24="","",M24/Z24) | AB24: REFlex | AC24: Synthetic example
A25: 21 | B25: 47774 | C25: 10:20 AM | D25: Ashran | E25: Epic | F25: 0.015127315 | G25: W | J25: 4 | K25: 5 | M25: 71.191827 | N25: 36.560967 | O25: =IF(OR(F25="",F25=0),"",M25/(F25*1440)) | P25: 1659 | AA25: =IF(Z25="","",M25/Z25) | AB25: REFlex
A26: 22 | B26: 47774 | C26: 10:38 AM | D26: The Battle for Gilneas | E26: Bases | F26: 0.0025231481 | G26: L | J26: 0 | K26: 0 | M26: 18.392027 | N26: 6.064767 | O26: =IF(OR(F26="",F26=0),"",M26/(F26*1440)) | P26: 249 | AA26: =IF(Z26="","",M26/Z26) | AB26: REFlex | AC26: Synthetic example
A27: 23 | B27: 47774 | C27: 11:00 AM | D27: Eye of the Storm | E27: Flag + Bases | F27: 0.011261574 | G27: L | J27: 7 | K27: 4 | M27: 54.861427 | N27: 14.312167 | O27: =IF(OR(F27="",F27=0),"",M27/(F27*1440)) | P27: 652 | AA27: =IF(Z27="","",M27/Z27) | AB27: REFlex
A28: 24 | B28: 47774 | C28: 11:17 AM | D28: Eye of the Storm | E28: Flag + Bases | F28: 0.0081597222 | G28: W | J28: 10 | K28: 10 | M28: 21.241627 | N28: 12.120167 | O28: =IF(OR(F28="",F28=0),"",M28/(F28*1440)) | P28: 931 | AA28: =IF(Z28="","",M28/Z28) | AB28: REFlex | AC28: Synthetic example
A29: 25 | B29: 47774 | C29: 11:29 AM | D29: Temple of Kotmogu | E29: Orbs | F29: 0.0045023148 | G29: L | J29: 7 | K29: 6 | M29: 17.898827 | N29: 12.805167 | O29: =IF(OR(F29="",F29=0),"",M29/(F29*1440)) | P29: 341 | AA29: =IF(Z29="","",M29/Z29) | AB29: REFlex
A30: 26 | B30: 47774 | C30: 11:43 AM | D30: Deephaul Ravine | E30: Carts | F30: 0.0040277778 | G30: L | J30: 0 | K30: 0 | M30: 3.157627 | N30: 4.722167 | O30: =IF(OR(F30="",F30=0),"",M30/(F30*1440)) | P30: 252 | AA30: =IF(Z30="","",M30/Z30) | AB30: REFlex | AC30: Synthetic example
A31: 27 | B31: 47774 | C31: 12:02 PM | D31: Twin Peaks | E31: Flag | F31: 0.0082986111 | G31: W | J31: 4 | K31: 9 | M31: 40.449027 | N31: 13.791567 | O31: =IF(OR(F31="",F31=0),"",M31/(F31*1440)) | P31: 1010 | AA31: =IF(Z31="","",M31/Z31) | AB31: REFlex
A32: 28 | B32: 47774 | C32: 12:25 PM | D32: Silvershard Mines | E32: Carts | F32: 0.0075810185 | G32: L | J32: 2 | K32: 3 | M32: 40.394227 | N32: 17.326167 | O32: =IF(OR(F32="",F32=0),"",M32/(F32*1440)) | P32: 584 | AA32: =IF(Z32="","",M32/Z32) | AB32: REFlex
A33: 29 | B33: 47774 | C33: 01:36 PM | D33: Deepwind Gorge | E33: Bases | F33: 0.011099537 | G33: W | J33: 4 | K33: 7 | M33: 25.872227 | N33: 7.352567 | O33: =IF(OR(F33="",F33=0),"",M33/(F33*1440)) | P33: 837 | AA33: =IF(Z33="","",M33/Z33) | AB33: REFlex
A34: 30 | B34: 47774 | C34: 01:57 PM | D34: The Battle for Gilneas | E34: Bases | F34: 0.0049652778 | G34: W | J34: 2 | K34: 7 | M34: 22.365027 | N34: 7.571767 | O34: =IF(OR(F34="",F34=0),"",M34/(F34*1440)) | P34: 945 | AA34: =IF(Z34="","",M34/Z34) | AB34: REFlex
A35: 31 | B35: 47774 | C35: 02:16 PM | D35: Arathi Basin | E35: Bases | F35: 0.010648148 | G35: L | J35: 10 | K35: 6 | M35: 23.515827 | N35: 18.531767 | O35: =IF(OR(F35="",F35=0),"",M35/(F35*1440)) | P35: 664 | AA35: =IF(Z35="","",M35/Z35) | AB35: REFlex
A36: 32 | B36: 47774 | C36: 02:30 PM | D36: Deephaul Ravine | E36: Carts | F36: 0.0050231481 | G36: L | J36: 0 | K36: 10 | M36: 22.008827 | N36: 5.982567 | O36: =IF(OR(F36="",F36=0),"",M36/(F36*1440)) | P36: 305 | AA36: =IF(Z36="","",M36/Z36) | AB36: REFlex
A37: 33 | B37: 47774 | C37: 02:49 PM | D37: Arathi Basin | E37: Bases | F37: 0.0092013889 | G37: L | H37: 816 | I37: 1517 | J37: 4 | K37: 3 | L37: 8 | M37: 32.612627 | N37: 17.298767 | O37: =IF(OR(F37="",F37=0),"",M37/(F37*1440)) | P37: 505 | Q37: 0 | R37: Base defense | S37: 18 | T37: 18 | Z37: 45 | AA37: =IF(Z37="","",M37/Z37) | AB37: REFlex + scoreboard | AC37: Synthetic example | AI37: No | AJ37: 1 of 1 (visible roster)
A38: 34 | B38: 47774 | C38: 03:00 PM | D38: Seething Shore | E38: Azerite | F38: 0.0038657407 | G38: L | J38: 0 | K38: 0 | M38: 9.048627 | N38: 8.284167 | O38: =IF(OR(F38="",F38=0),"",M38/(F38*1440)) | P38: 230 | AA38: =IF(Z38="","",M38/Z38) | AB38: REFlex | AC38: Synthetic example
A39: 35 | B39: 47774 | C39: 03:19 PM | D39: Deepwind Gorge | E39: Bases | F39: 0.0093865741 | G39: W | J39: 10 | K39: 2 | M39: 31.790627 | N39: 15.353367 | O39: =IF(OR(F39="",F39=0),"",M39/(F39*1440)) | P39: 887 | AA39: =IF(Z39="","",M39/Z39) | AB39: REFlex
A40: 36 | B40: 47774 | C40: 03:41 PM | D40: The Battle for Gilneas | E40: Bases | F40: 0.0093055556 | G40: L | J40: 0 | K40: 2 | M40: 9.733627 | N40: 8.448567 | O40: =IF(OR(F40="",F40=0),"",M40/(F40*1440)) | P40: 508 | AA40: =IF(Z40="","",M40/Z40) | AB40: REFlex
A41: 37 | B41: 47774 | C41: 03:56 PM | D41: The Battle for Gilneas | E41: Bases | F41: 0.0069212963 | G41: W | J41: 7 | K41: 2 | M41: 7.651227 | N41: 6.201767 | O41: =IF(OR(F41="",F41=0),"",M41/(F41*1440)) | P41: 927 | AA41: =IF(Z41="","",M41/Z41) | AB41: REFlex
...

Sheet PG Roster
A1: Asterknight — Match Rosters
A2: One row per player per match. Game # links to the Matches tab. Use this to spot recurring enemy players and premades.
A4: Game # | B4: Player | C4: Realm | D4: Faction | E4: KB | F4: HK | G4: Deaths | H4: Damage (M) | I4: Healing (M) | J4: Orb possessions | K4: Victory points | L4: Notes | M4: Times seen | N4: Person | O4: Group | P4: Status
A5: 48 | B5: Player0685 | C5: ExampleWorld126 | D5: Horde | E5: 2 | F5: 5 | G5: 4 | H5: 52.148827 | I5: 5.023567 | J5: 18 | K5: 183 | M5: =COUNTIFS($B$5:$B$2000,B5,$C$5:$C$2000,C5)+COUNTIFS('GM Roster'!$B$5:$B$2000,B5,'GM Roster'!$C$5:$C$2000,C5) | N5: =IFERROR(INDEX('Known Players'!$C$5:$C$500,MATCH(B5&"|"&C5,'Known Players'!$F$5:$F$500,0)),"") | O5: =IFERROR(INDEX('Known Players'!$D$5:$D$500,MATCH(B5&"|"&C5,'Known Players'!$F$5:$F$500,0)),"") | P5: =IFERROR(INDEX('Known Players'!$G$5:$G$500,MATCH(B5&"|"&C5,'Known Players'!$F$5:$F$500,0)),"")
A6: 48 | B6: Snowflare | C6: SandboxRealm | D6: Horde | E6: 5 | F6: 8 | G6: 0 | H6: 49.408827 | I6: 4.749567 | J6: 0 | K6: 67 | M6: =COUNTIFS($B$5:$B$2000,B6,$C$5:$C$2000,C6)+COUNTIFS('GM Roster'!$B$5:$B$2000,B6,'GM Roster'!$C$5:$C$2000,C6) | N6: =IFERROR(INDEX('Known Players'!$C$5:$C$500,MATCH(B6&"|"&C6,'Known Players'!$F$5:$F$500,0)),"") | O6: =IFERROR(INDEX('Known Players'!$D$5:$D$500,MATCH(B6&"|"&C6,'Known Players'!$F$5:$F$500,0)),"") | P6: =IFERROR(INDEX('Known Players'!$G$5:$G$500,MATCH(B6&"|"&C6,'Known Players'!$F$5:$F$500,0)),"")
A7: 48 | B7: Player0942 | C7: ExampleWorld164 | D7: Alliance | E7: 0 | F7: 0 | G7: 7 | H7: 46.668827 | I7: 9.955567 | J7: 0 | K7: 0 | M7: =COUNTIFS($B$5:$B$2000,B7,$C$5:$C$2000,C7)+COUNTIFS('GM Roster'!$B$5:$B$2000,B7,'GM Roster'!$C$5:$C$2000,C7) | N7: =IFERROR(INDEX('Known Players'!$C$5:$C$500,MATCH(B7&"|"&C7,'Known Players'!$F$5:$F$500,0)),"") | O7: =IFERROR(INDEX('Known Players'!$D$5:$D$500,MATCH(B7&"|"&C7,'Known Players'!$F$5:$F$500,0)),"") | P7: =IFERROR(INDEX('Known Players'!$G$5:$G$500,MATCH(B7&"|"&C7,'Known Players'!$F$5:$F$500,0)),"")
A8: 48 | B8: Player0200 | C8: ExampleWorld179 | D8: Horde | E8: 6 | F8: 5 | G8: 4 | H8: 41.188827 | I8: 1.201267 | J8: 18 | K8: 305 | M8: =COUNTIFS($B$5:$B$2000,B8,$C$5:$C$2000,C8)+COUNTIFS('GM Roster'!$B$5:$B$2000,B8,'GM Roster'!$C$5:$C$2000,C8) | N8: =IFERROR(INDEX('Known Players'!$C$5:$C$500,MATCH(B8&"|"&C8,'Known Players'!$F$5:$F$500,0)),"") | O8: =IFERROR(INDEX('Known Players'!$D$5:$D$500,MATCH(B8&"|"&C8,'Known Players'!$F$5:$F$500,0)),"") | P8: =IFERROR(INDEX('Known Players'!$G$5:$G$500,MATCH(B8&"|"&C8,'Known Players'!$F$5:$F$500,0)),"")
A9: 48 | B9: Player0116 | C9: ExampleWorld164 | D9: Alliance | E9: 7 | F9: 0 | G9: 8 | H9: 38.448827 | I9: 5.297567 | J9: 0 | K9: 37 | M9: =COUNTIFS($B$5:$B$2000,B9,$C$5:$C$2000,C9)+COUNTIFS('GM Roster'!$B$5:$B$2000,B9,'GM Roster'!$C$5:$C$2000,C9) | N9: =IFERROR(INDEX('Known Players'!$C$5:$C$500,MATCH(B9&"|"&C9,'Known Players'!$F$5:$F$500,0)),"") | O9: =IFERROR(INDEX('Known Players'!$D$5:$D$500,MATCH(B9&"|"&C9,'Known Players'!$F$5:$F$500,0)),"") | P9: =IFERROR(INDEX('Known Players'!$G$5:$G$500,MATCH(B9&"|"&C9,'Known Players'!$F$5:$F$500,0)),"")
A10: 48 | B10: Player0044 | C10: ExampleWorld164 | D10: Alliance | E10: 4 | F10: 0 | G10: 8 | H10: 35.708827 | I10: 6.119567 | J10: 20 | K10: 105 | M10: =COUNTIFS($B$5:$B$2000,B10,$C$5:$C$2000,C10)+COUNTIFS('GM Roster'!$B$5:$B$2000,B10,'GM Roster'!$C$5:$C$2000,C10) | N10: =IFERROR(INDEX('Known Players'!$C$5:$C$500,MATCH(B10&"|"&C10,'Known Players'!$F$5:$F$500,0)),"") | O10: =IFERROR(INDEX('Known Players'!$D$5:$D$500,MATCH(B10&"|"&C10,'Known Players'!$F$5:$F$500,0)),"") | P10: =IFERROR(INDEX('Known Players'!$G$5:$G$500,MATCH(B10&"|"&C10,'Known Players'!$F$5:$F$500,0)),"")
A11: 48 | B11: Asterknight | C11: exampleworld001 | D11: Horde | E11: 7 | F11: 2 | G11: 4 | H11: 32.530427 | I11: 10.585767 | J11: 19 | K11: 127 | M11: =COUNTIFS($B$5:$B$2000,B11,$C$5:$C$2000,C11)+COUNTIFS('GM Roster'!$B$5:$B$2000,B11,'GM Roster'!$C$5:$C$2000,C11) | N11: =IFERROR(INDEX('Known Players'!$C$5:$C$500,MATCH(B11&"|"&C11,'Known Players'!$F$5:$F$500,0)),"") | O11: =IFERROR(INDEX('Known Players'!$D$5:$D$500,MATCH(B11&"|"&C11,'Known Players'!$F$5:$F$500,0)),"") | P11: =IFERROR(INDEX('Known Players'!$G$5:$G$500,MATCH(B11&"|"&C11,'Known Players'!$F$5:$F$500,0)),"")
A12: 48 | B12: Player0603 | C12: ExampleWorld164 | D12: Alliance | E12: 4 | F12: 5 | G12: 2 | H12: 27.488827 | I12: 14.613567 | J12: 0 | K12: 27 | M12: =COUNTIFS($B$5:$B$2000,B12,$C$5:$C$2000,C12)+COUNTIFS('GM Roster'!$B$5:$B$2000,B12,'GM Roster'!$C$5:$C$2000,C12) | N12: =IFERROR(INDEX('Known Players'!$C$5:$C$500,MATCH(B12&"|"&C12,'Known Players'!$F$5:$F$500,0)),"") | O12: =IFERROR(INDEX('Known Players'!$D$5:$D$500,MATCH(B12&"|"&C12,'Known Players'!$F$5:$F$500,0)),"") | P12: =IFERROR(INDEX('Known Players'!$G$5:$G$500,MATCH(B12&"|"&C12,'Known Players'!$F$5:$F$500,0)),"")
A13: 48 | B13: Emberward | C13: SandboxRealm | D13: Horde | E13: 0 | F13: 8 | G13: 0 | H13: 27.488827 | I13: 2.749367 | J13: 0 | K13: 87 | M13: =COUNTIFS($B$5:$B$2000,B13,$C$5:$C$2000,C13)+COUNTIFS('GM Roster'!$B$5:$B$2000,B13,'GM Roster'!$C$5:$C$2000,C13) | N13: =IFERROR(INDEX('Known Players'!$C$5:$C$500,MATCH(B13&"|"&C13,'Known Players'!$F$5:$F$500,0)),"") | O13: =IFERROR(INDEX('Known Players'!$D$5:$D$500,MATCH(B13&"|"&C13,'Known Players'!$F$5:$F$500,0)),"") | P13: =IFERROR(INDEX('Known Players'!$G$5:$G$500,MATCH(B13&"|"&C13,'Known Players'!$F$5:$F$500,0)),"")
A14: 48 | B14: Thornpaw | C14: SandboxRealm | D14: Horde | E14: 8 | F14: 10 | G14: 4 | H14: 25.570827 | I14: 6.941567 | J14: 18 | K14: 241 | M14: =COUNTIFS($B$5:$B$2000,B14,$C$5:$C$2000,C14)+COUNTIFS('GM Roster'!$B$5:$B$2000,B14,'GM Roster'!$C$5:$C$2000,C14) | N14: =IFERROR(INDEX('Known Players'!$C$5:$C$500,MATCH(B14&"|"&C14,'Known Players'!$F$5:$F$500,0)),"") | O14: =IFERROR(INDEX('Known Players'!$D$5:$D$500,MATCH(B14&"|"&C14,'Known Players'!$F$5:$F$500,0)),"") | P14: =IFERROR(INDEX('Known Players'!$G$5:$G$500,MATCH(B14&"|"&C14,'Known Players'!$F$5:$F$500,0)),"")
A15: 48 | B15: Player0391 | C15: ExampleWorld003 | D15: Horde | E15: 4 | F15: 10 | G15: 4 | H15: 21.460827 | I15: 10.777567 | J15: 19 | K15: 329 | M15: =COUNTIFS($B$5:$B$2000,B15,$C$5:$C$2000,C15)+COUNTIFS('GM Roster'!$B$5:$B$2000,B15,'GM Roster'!$C$5:$C$2000,C15) | N15: =IFERROR(INDEX('Known Players'!$C$5:$C$500,MATCH(B15&"|"&C15,'Known Players'!$F$5:$F$500,0)),"") | O15: =IFERROR(INDEX('Known Players'!$D$5:$D$500,MATCH(B15&"|"&C15,'Known Players'!$F$5:$F$500,0)),"") | P15: =IFERROR(INDEX('Known Players'!$G$5:$G$500,MATCH(B15&"|"&C15,'Known Players'!$F$5:$F$500,0)),"")
A16: 48 | B16: Player0348 | C16: ExampleWorld130 | D16: Alliance | E16: 0 | F16: 2 | G16: 5 | H16: 18.720827 | I16: 30.231567 | J16: 19 | K16: 81 | M16: =COUNTIFS($B$5:$B$2000,B16,$C$5:$C$2000,C16)+COUNTIFS('GM Roster'!$B$5:$B$2000,B16,'GM Roster'!$C$5:$C$2000,C16) | N16: =IFERROR(INDEX('Known Players'!$C$5:$C$500,MATCH(B16&"|"&C16,'Known Players'!$F$5:$F$500,0)),"") | O16: =IFERROR(INDEX('Known Players'!$D$5:$D$500,MATCH(B16&"|"&C16,'Known Players'!$F$5:$F$500,0)),"") | P16: =IFERROR(INDEX('Known Players'!$G$5:$G$500,MATCH(B16&"|"&C16,'Known Players'!$F$5:$F$500,0)),"")
... A36: 49 | B36: Player0891 | C36: ExampleWorld133 | D36: Alliance | E36: 0 | F36: 7 | G36: 5 | H36: 14.336827 | I36: 38.451567 | J36: 20 | K36: 111 | M36: =COUNTIFS($B$5:$B$2000,B36,$C$5:$C$2000,C36)+COUNTIFS('GM Roster'!$B$5:$B$2000,B36,'GM Roster'!$C$5:$C$2000,C36) | N36: =IFERROR(INDEX('Known Players'!$C$5:$C$500,MATCH(B36&"|"&C36,'Known Players'!$F$5:$F$500,0)),"") | O36: =IFERROR(INDEX('Known Players'!$D$5:$D$500,MATCH(B36&"|"&C36,'Known Players'!$F$5:$F$500,0)),"") | P36: =IFERROR(INDEX('Known Players'!$G$5:$G$500,MATCH(B36&"|"&C36,'Known Players'!$F$5:$F$500,0)),"")
A37: 50 | B37: Player0180 | C37: SandboxRealm | D37: Horde | E37: 0 | F37: 0 | G37: 7 | H37: 5.020827 | I37: 101.47157 | M37: =COUNTIFS($B$5:$B$2000,B37,$C$5:$C$2000,C37)+COUNTIFS('GM Roster'!$B$5:$B$2000,B37,'GM Roster'!$C$5:$C$2000,C37) | N37: =IFERROR(INDEX('Known Players'!$C$5:$C$500,MATCH(B37&"|"&C37,'Known Players'!$F$5:$F$500,0)),"") | O37: =IFERROR(INDEX('Known Players'!$D$5:$D$500,MATCH(B37&"|"&C37,'Known Players'!$F$5:$F$500,0)),"") | P37: =IFERROR(INDEX('Known Players'!$G$5:$G$500,MATCH(B37&"|"&C37,'Known Players'!$F$5:$F$500,0)),"")
A38: 50 | B38: Player0382 | C38: ExampleWorld102 | D38: Horde | E38: 0 | F38: 1 | G38: 7 | H38: 6.116827 | I38: 43.931567 | M38: =COUNTIFS($B$5:$B$2000,B38,$C$5:$C$2000,C38)+COUNTIFS('GM Roster'!$B$5:$B$2000,B38,'GM Roster'!$C$5:$C$2000,C38) | N38: =IFERROR(INDEX('Known Players'!$C$5:$C$500,MATCH(B38&"|"&C38,'Known Players'!$F$5:$F$500,0)),"") | O38: =IFERROR(INDEX('Known Players'!$D$5:$D$500,MATCH(B38&"|"&C38,'Known Players'!$F$5:$F$500,0)),"") | P38: =IFERROR(INDEX('Known Players'!$G$5:$G$500,MATCH(B38&"|"&C38,'Known Players'!$F$5:$F$500,0)),"")
A39: 50 | B39: Player0510 | C39: ExampleWorld029 | D39: Horde | E39: 0 | F39: 1 | G39: 10 | H39: 20.364827 | I39: 26.669567 | M39: =COUNTIFS($B$5:$B$2000,B39,$C$5:$C$2000,C39)+COUNTIFS('GM Roster'!$B$5:$B$2000,B39,'GM Roster'!$C$5:$C$2000,C39) | N39: =IFERROR(INDEX('Known Players'!$C$5:$C$500,MATCH(B39&"|"&C39,'Known Players'!$F$5:$F$500,0)),"") | O39: =IFERROR(INDEX('Known Players'!$D$5:$D$500,MATCH(B39&"|"&C39,'Known Players'!$F$5:$F$500,0)),"") | P39: =IFERROR(INDEX('Known Players'!$G$5:$G$500,MATCH(B39&"|"&C39,'Known Players'!$F$5:$F$500,0)),"")
A40: 50 | B40: Snowflare | C40: SandboxRealm | D40: Horde | E40: 2 | F40: 4 | G40: 10 | H40: 52.148827 | I40: 19.271567 | M40: =COUNTIFS($B$5:$B$2000,B40,$C$5:$C$2000,C40)+COUNTIFS('GM Roster'!$B$5:$B$2000,B40,'GM Roster'!$C$5:$C$2000,C40) | N40: =IFERROR(INDEX('Known Players'!$C$5:$C$500,MATCH(B40&"|"&C40,'Known Players'!$F$5:$F$500,0)),"") | O40: =IFERROR(INDEX('Known Players'!$D$5:$D$500,MATCH(B40&"|"&C40,'Known Players'!$F$5:$F$500,0)),"") | P40: =IFERROR(INDEX('Known Players'!$G$5:$G$500,MATCH(B40&"|"&C40,'Known Players'!$F$5:$F$500,0)),"")
A41: 50 | B41: Player0359 | C41: ExampleWorld174 | D41: Horde | E41: 0 | F41: 8 | G41: 10 | H41: 6.116827 | I41: 19.271567 | M41: =COUNTIFS($B$5:$B$2000,B41,$C$5:$C$2000,C41)+COUNTIFS('GM Roster'!$B$5:$B$2000,B41,'GM Roster'!$C$5:$C$2000,C41) | N41: =IFERROR(INDEX('Known Players'!$C$5:$C$500,MATCH(B41&"|"&C41,'Known Players'!$F$5:$F$500,0)),"") | O41: =IFERROR(INDEX('Known Players'!$D$5:$D$500,MATCH(B41&"|"&C41,'Known Players'!$F$5:$F$500,0)),"") | P41: =IFERROR(INDEX('Known Players'!$G$5:$G$500,MATCH(B41&"|"&C41,'Known Players'!$F$5:$F$500,0)),"")
A42: 50 | B42: Player0488 | C42: ExampleWorld169 | D42: Horde | E42: 10 | F42: 10 | G42: 0 | H42: 93.248827 | I42: 15.709567 | M42: =COUNTIFS($B$5:$B$2000,B42,$C$5:$C$2000,C42)+COUNTIFS('GM Roster'!$B$5:$B$2000,B42,'GM Roster'!$C$5:$C$2000,C42) | N42: =IFERROR(INDEX('Known Players'!$C$5:$C$500,MATCH(B42&"|"&C42,'Known Players'!$F$5:$F$500,0)),"") | O42: =IFERROR(INDEX('Known Players'!$D$5:$D$500,MATCH(B42&"|"&C42,'Known Players'!$F$5:$F$500,0)),"") | P42: =IFERROR(INDEX('Known Players'!$G$5:$G$500,MATCH(B42&"|"&C42,'Known Players'!$F$5:$F$500,0)),"")
A43: 50 | B43: Thornpaw | C43: SandboxRealm | D43: Horde | E43: 4 | F43: 4 | G43: 10 | H43: 25.844827 | I43: 15.435567 | M43: =COUNTIFS($B$5:$B$2000,B43,$C$5:$C$2000,C43)+COUNTIFS('GM Roster'!$B$5:$B$2000,B43,'GM Roster'!$C$5:$C$2000,C43) | N43: =IFERROR(INDEX('Known Players'!$C$5:$C$500,MATCH(B43&"|"&C43,'Known Players'!$F$5:$F$500,0)),"") | O43: =IFERROR(INDEX('Known Players'!$D$5:$D$500,MATCH(B43&"|"&C43,'Known Players'!$F$5:$F$500,0)),"") | P43: =IFERROR(INDEX('Known Players'!$G$5:$G$500,MATCH(B43&"|"&C43,'Known Players'!$F$5:$F$500,0)),"")
A44: 50 | B44: Asterknight | C44: exampleworld001 | D44: Horde | E44: 10 | F44: 4 | G44: 7 | H44: 23.296627 | I44: 10.695367 | L44: Synthetic example | M44: =COUNTIFS($B$5:$B$2000,B44,$C$5:$C$2000,C44)+COUNTIFS('GM Roster'!$B$5:$B$2000,B44,'GM Roster'!$C$5:$C$2000,C44) | N44: =IFERROR(INDEX('Known Players'!$C$5:$C$500,MATCH(B44&"|"&C44,'Known Players'!$F$5:$F$500,0)),"") | O44: =IFERROR(INDEX('Known Players'!$D$5:$D$500,MATCH(B44&"|"&C44,'Known Players'!$F$5:$F$500,0)),"") | P44: =IFERROR(INDEX('Known Players'!$G$5:$G$500,MATCH(B44&"|"&C44,'Known Players'!$F$5:$F$500,0)),"")
A45: 50 | B45: Emberward | C45: SandboxRealm | D45: Horde | E45: 5 | F45: 3 | G45: 10 | H45: 38.448827 | I45: 6.119567 | M45: =COUNTIFS($B$5:$B$2000,B45,$C$5:$C$2000,C45)+COUNTIFS('GM Roster'!$B$5:$B$2000,B45,'GM Roster'!$C$5:$C$2000,C45) | N45: =IFERROR(INDEX('Known Players'!$C$5:$C$500,MATCH(B45&"|"&C45,'Known Players'!$F$5:$F$500,0)),"") | O45: =IFERROR(INDEX('Known Players'!$D$5:$D$500,MATCH(B45&"|"&C45,'Known Players'!$F$5:$F$500,0)),"") | P45: =IFERROR(INDEX('Known Players'!$G$5:$G$500,MATCH(B45&"|"&C45,'Known Players'!$F$5:$F$500,0)),"")
A46: 50 | B46: Player0018 | C46: ExampleWorld144 | D46: Horde | E46: 7 | F46: 0 | G46: 0 | H46: 38.448827 | I46: 3.105567 | M46: =COUNTIFS($B$5:$B$2000,B46,$C$5:$C$2000,C46)+COUNTIFS('GM Roster'!$B$5:$B$2000,B46,'GM Roster'!$C$5:$C$2000,C46) | N46: =IFERROR(INDEX('Known Players'!$C$5:$C$500,MATCH(B46&"|"&C46,'Known Players'!$F$5:$F$500,0)),"") | O46: =IFERROR(INDEX('Known Players'!$D$5:$D$500,MATCH(B46&"|"&C46,'Known Players'!$F$5:$F$500,0)),"") | P46: =IFERROR(INDEX('Known Players'!$G$5:$G$500,MATCH(B46&"|"&C46,'Known Players'!$F$5:$F$500,0)),"")
A47: 50 | B47: Player0419 | C47: ExampleWorld063 | D47: Horde | E47: 0 | F47: 9 | G47: 0 | H47: 11.596827 | I47: 2.831567 | M47: =COUNTIFS($B$5:$B$2000,B47,$C$5:$C$2000,C47)+COUNTIFS('GM Roster'!$B$5:$B$2000,B47,'GM Roster'!$C$5:$C$2000,C47) | N47: =IFERROR(INDEX('Known Players'!$C$5:$C$500,MATCH(B47&"|"&C47,'Known Players'!$F$5:$F$500,0)),"") | O47: =IFERROR(INDEX('Known Players'!$D$5:$D$500,MATCH(B47&"|"&C47,'Known Players'!$F$5:$F$500,0)),"") | P47: =IFERROR(INDEX('Known Players'!$G$5:$G$500,MATCH(B47&"|"&C47,'Known Players'!$F$5:$F$500,0)),"")
A48: 50 | B48: Player0122 | C48: ExampleWorld023 | D48: Horde | E48: 10 | F48: 10 | G48: 10 | H48: 27.488827 | I48: 2.831567 | M48: =COUNTIFS($B$5:$B$2000,B48,$C$5:$C$2000,C48)+COUNTIFS('GM Roster'!$B$5:$B$2000,B48,'GM Roster'!$C$5:$C$2000,C48) | N48: =IFERROR(INDEX('Known Players'!$C$5:$C$500,MATCH(B48&"|"&C48,'Known Players'!$F$5:$F$500,0)),"") | O48: =IFERROR(INDEX('Known Players'!$D$5:$D$500,MATCH(B48&"|"&C48,'Known Players'!$F$5:$F$500,0)),"") | P48: =IFERROR(INDEX('Known Players'!$G$5:$G$500,MATCH(B48&"|"&C48,'Known Players'!$F$5:$F$500,0)),"")
A49: 50 | B49: Player0915 | C49: ExampleWorld084 | D49: Horde | E49: 7 | F49: 2 | G49: 7 | H49: 30.228827 | I49: 2.719227 | M49: =COUNTIFS($B$5:$B$2000,B49,$C$5:$C$2000,C49)+COUNTIFS('GM Roster'!$B$5:$B$2000,B49,'GM Roster'!$C$5:$C$2000,C49) | N49: =IFERROR(INDEX('Known Players'!$C$5:$C$500,MATCH(B49&"|"&C49,'Known Players'!$F$5:$F$500,0)),"") | O49: =IFERROR(INDEX('Known Players'!$D$5:$D$500,MATCH(B49&"|"&C49,'Known Players'!$F$5:$F$500,0)),"") | P49: =IFERROR(INDEX('Known Players'!$G$5:$G$500,MATCH(B49&"|"&C49,'Known Players'!$F$5:$F$500,0)),"")
A50: 50 | B50: Player0093 | C50: ExampleWorld023 | D50: Horde | E50: 0 | F50: 0 | G50: 7 | H50: 27.488827 | I50: 2.376727 | M50: =COUNTIFS($B$5:$B$2000,B50,$C$5:$C$2000,C50)+COUNTIFS('GM Roster'!$B$5:$B$2000,B50,'GM Roster'!$C$5:$C$2000,C50) | N50: =IFERROR(INDEX('Known Players'!$C$5:$C$500,MATCH(B50&"|"&C50,'Known Players'!$F$5:$F$500,0)),"") | O50: =IFERROR(INDEX('Known Players'!$D$5:$D$500,MATCH(B50&"|"&C50,'Known Players'!$F$5:$F$500,0)),"") | P50: =IFERROR(INDEX('Known Players'!$G$5:$G$500,MATCH(B50&"|"&C50,'Known Players'!$F$5:$F$500,0)),"")
A51: 50 | B51: Player0599 | C51: ExampleWorld143 | D51: Horde | E51: 5 | F51: 1 | G51: 0 | H51: 49.408827 | I51: 2.316447 | M51: =COUNTIFS($B$5:$B$2000,B51,$C$5:$C$2000,C51)+COUNTIFS('GM Roster'!$B$5:$B$2000,B51,'GM Roster'!$C$5:$C$2000,C51) | N51: =IFERROR(INDEX('Known Players'!$C$5:$C$500,MATCH(B51&"|"&C51,'Known Players'!$F$5:$F$500,0)),"") | O51: =IFERROR(INDEX('Known Players'!$D$5:$D$500,MATCH(B51&"|"&C51,'Known Players'!$F$5:$F$500,0)),"") | P51: =IFERROR(INDEX('Known Players'!$G$5:$G$500,MATCH(B51&"|"&C51,'Known Players'!$F$5:$F$500,0)),"")
A52: 50 | B52: Player0429 | C52: ExampleWorld143 | D52: Alliance | E52: 4 | F52: 8 | G52: 4 | H52: 2.379467 | I52: 126.13157 | M52: =COUNTIFS($B$5:$B$2000,B52,$C$5:$C$2000,C52)+COUNTIFS('GM Roster'!$B$5:$B$2000,B52,'GM Roster'!$C$5:$C$2000,C52) | N52: =IFERROR(INDEX('Known Players'!$C$5:$C$500,MATCH(B52&"|"&C52,'Known Players'!$F$5:$F$500,0)),"") | O52: =IFERROR(INDEX('Known Players'!$D$5:$D$500,MATCH(B52&"|"&C52,'Known Players'!$F$5:$F$500,0)),"") | P52: =IFERROR(INDEX('Known Players'!$G$5:$G$500,MATCH(B52&"|"&C52,'Known Players'!$F$5:$F$500,0)),"")
A53: 50 | B53: Player0745 | C53: ExampleWorld133 | D53: Alliance | E53: 4 | F53: 6 | G53: 7 | H53: 6.938827 | I53: 90.511567 | L53: Synthetic example | M53: =COUNTIFS($B$5:$B$2000,B53,$C$5:$C$2000,C53)+COUNTIFS('GM Roster'!$B$5:$B$2000,B53,'GM Roster'!$C$5:$C$2000,C53) | N53: =IFERROR(INDEX('Known Players'!$C$5:$C$500,MATCH(B53&"|"&C53,'Known Players'!$F$5:$F$500,0)),"") | O53: =IFERROR(INDEX('Known Players'!$D$5:$D$500,MATCH(B53&"|"&C53,'Known Players'!$F$5:$F$500,0)),"") | P53: =IFERROR(INDEX('Known Players'!$G$5:$G$500,MATCH(B53&"|"&C53,'Known Players'!$F$5:$F$500,0)),"")
A54: 50 | B54: Player0267 | C54: ExampleWorld039 | D54: Alliance | E54: 0 | F54: 5 | G54: 4 | H54: 15.158827 | I54: 87.771567 | M54: =COUNTIFS($B$5:$B$2000,B54,$C$5:$C$2000,C54)+COUNTIFS('GM Roster'!$B$5:$B$2000,B54,'GM Roster'!$C$5:$C$2000,C54) | N54: =IFERROR(INDEX('Known Players'!$C$5:$C$500,MATCH(B54&"|"&C54,'Known Players'!$F$5:$F$500,0)),"") | O54: =IFERROR(INDEX('Known Players'!$D$5:$D$500,MATCH(B54&"|"&C54,'Known Players'!$F$5:$F$500,0)),"") | P54: =IFERROR(INDEX('Known Players'!$G$5:$G$500,MATCH(B54&"|"&C54,'Known Players'!$F$5:$F$500,0)),"")
A55: 50 | B55: Player0405 | C55: ExampleWorld063 | D55: Alliance | E55: 0 | F55: 4 | G55: 2 | H55: 38.448827 | I55: 17.627567 | M55: =COUNTIFS($B$5:$B$2000,B55,$C$5:$C$2000,C55)+COUNTIFS('GM Roster'!$B$5:$B$2000,B55,'GM Roster'!$C$5:$C$2000,C55) | N55: =IFERROR(INDEX('Known Players'!$C$5:$C$500,MATCH(B55&"|"&C55,'Known Players'!$F$5:$F$500,0)),"") | O55: =IFERROR(INDEX('Known Players'!$D$5:$D$500,MATCH(B55&"|"&C55,'Known Players'!$F$5:$F$500,0)),"") | P55: =IFERROR(INDEX('Known Players'!$G$5:$G$500,MATCH(B55&"|"&C55,'Known Players'!$F$5:$F$500,0)),"")
A56: 50 | B56: Player0349 | C56: ExampleWorld133 | D56: Alliance | E56: 0 | F56: 1 | G56: 10 | H56: 49.408827 | I56: 15.161567 | M56: =COUNTIFS($B$5:$B$2000,B56,$C$5:$C$2000,C56)+COUNTIFS('GM Roster'!$B$5:$B$2000,B56,'GM Roster'!$C$5:$C$2000,C56) | N56: =IFERROR(INDEX('Known Players'!$C$5:$C$500,MATCH(B56&"|"&C56,'Known Players'!$F$5:$F$500,0)),"") | O56: =IFERROR(INDEX('Known Players'!$D$5:$D$500,MATCH(B56&"|"&C56,'Known Players'!$F$5:$F$500,0)),"") | P56: =IFERROR(INDEX('Known Players'!$G$5:$G$500,MATCH(B56&"|"&C56,'Known Players'!$F$5:$F$500,0)),"")
A57: 50 | B57: Player0403 | C57: ExampleWorld133 | D57: Alliance | E57: 2 | F57: 9 | G57: 4 | H57: 41.188827 | I57: 14.887567 | M57: =COUNTIFS($B$5:$B$2000,B57,$C$5:$C$2000,C57)+COUNTIFS('GM Roster'!$B$5:$B$2000,B57,'GM Roster'!$C$5:$C$2000,C57) | N57: =IFERROR(INDEX('Known Players'!$C$5:$C$500,MATCH(B57&"|"&C57,'Known Players'!$F$5:$F$500,0)),"") | O57: =IFERROR(INDEX('Known Players'!$D$5:$D$500,MATCH(B57&"|"&C57,'Known Players'!$F$5:$F$500,0)),"") | P57: =IFERROR(INDEX('Known Players'!$G$5:$G$500,MATCH(B57&"|"&C57,'Known Players'!$F$5:$F$500,0)),"")
A58: 50 | B58: Player0868 | C58: ExampleWorld150 | D58: Alliance | E58: 7 | F58: 9 | G58: 4 | H58: 41.188827 | I58: 11.325567 | M58: =COUNTIFS($B$5:$B$2000,B58,$C$5:$C$2000,C58)+COUNTIFS('GM Roster'!$B$5:$B$2000,B58,'GM Roster'!$C$5:$C$2000,C58) | N58: =IFERROR(INDEX('Known Players'!$C$5:$C$500,MATCH(B58&"|"&C58,'Known Players'!$F$5:$F$500,0)),"") | O58: =IFERROR(INDEX('Known Players'!$D$5:$D$500,MATCH(B58&"|"&C58,'Known Players'!$F$5:$F$500,0)),"") | P58: =IFERROR(INDEX('Known Players'!$G$5:$G$500,MATCH(B58&"|"&C58,'Known Players'!$F$5:$F$500,0)),"")
A59: 50 | B59: Player0602 | C59: ExampleWorld129 | D59: Alliance | E59: 5 | F59: 3 | G59: 7 | H59: 25.570827 | I59: 9.407567 | M59: =COUNTIFS($B$5:$B$2000,B59,$C$5:$C$2000,C59)+COUNTIFS('GM Roster'!$B$5:$B$2000,B59,'GM Roster'!$C$5:$C$2000,C59) | N59: =IFERROR(INDEX('Known Players'!$C$5:$C$500,MATCH(B59&"|"&C59,'Known Players'!$F$5:$F$500,0)),"") | O59: =IFERROR(INDEX('Known Players'!$D$5:$D$500,MATCH(B59&"|"&C59,'Known Players'!$F$5:$F$500,0)),"") | P59: =IFERROR(INDEX('Known Players'!$G$5:$G$500,MATCH(B59&"|"&C59,'Known Players'!$F$5:$F$500,0)),"")
A60: 50 | B60: Player0727 | C60: ExampleWorld013 | D60: Alliance | E60: 4 | F60: 0 | G60: 4 | H60: 18.172827 | I60: 9.133567 | L60: Synthetic example | M60: =COUNTIFS($B$5:$B$2000,B60,$C$5:$C$2000,C60)+COUNTIFS('GM Roster'!$B$5:$B$2000,B60,'GM Roster'!$C$5:$C$2000,C60) | N60: =IFERROR(INDEX('Known Players'!$C$5:$C$500,MATCH(B60&"|"&C60,'Known Players'!$F$5:$F$500,0)),"") | O60: =IFERROR(INDEX('Known Players'!$D$5:$D$500,MATCH(B60&"|"&C60,'Known Players'!$F$5:$F$500,0)),"") | P60: =IFERROR(INDEX('Known Players'!$G$5:$G$500,MATCH(B60&"|"&C60,'Known Players'!$F$5:$F$500,0)),"")
...

Sheet PG Arena
A1: Asterknight — Arena Log
A2: Games 1-2 from REFlex; games 3+ from scoreboards.
A4: # | B4: Date | C4: Arena | D4: Bracket | E4: Result | F4: Partner | G4: Opponents | H4: Duration | I4: KB | J4: Damage (M) | K4: Healing (M) | L4: Conquest | M4: Notes
A5: 1 | B5: 47773 | C5: TTP | D5: 2v2 skirmish | E5: W | G5: 1 visible icon | H5: 1:17 | J5: 2.297267 | K5: 1.461567
A6: 2 | B6: 47774 | C6: TR | D6: 2v2 skirmish | E6: L | G6: 2 enemies | H6: 1:03 | J6: 2.532907 | K6: 2.546607
A7: 3 | B7: 47777 | D7: 2v2 skirmish (unrated, for weekly missions) | E7: W | F7: Player0680-ExampleWorld017 (Frost Death Knight) | G7: Player0400-ExampleWorld104 (Arms Warrior), Player0107-ExampleWorld104 (Mage) | I7: 7 | J7: 2.828827 | K7: 2.582227 | L7: 62 | M7: Synthetic example
A8: 4 | B8: 47777 | D8: 2v2 skirmish (unrated, for weekly missions) | E8: L | F8: Player0400-ExampleWorld104 (Arms Warrior) | G8: Player0107-ExampleWorld104 (Mage), Player0608-ExampleWorld023 (Warlock) | H8: ~2:00 | I8: 0 | J8: 2.513727 | K8: 2.467147 | L8: 0 | M8: Synthetic example
A9: 5 | B9: 47777 | D9: 2v2 skirmish (unrated, for weekly missions) | E9: W | F9: Player0928-ExampleWorld104 | G9: Player0572-ExampleWorld104, Player0686-ExampleWorld164 | I9: 4 | J9: 2.798687 | K9: 1.993127 | L9: 26 | M9: Synthetic example
A10: 6 | B10: 47777 | D10: 2v2 skirmish (unrated, for weekly missions) | E10: W | F10: Emberguard-SandboxRealm (Buddy A, MM Hunter) | G10: Player0079-ExampleWorld005, Player0944-ExampleWorld144 | I10: 0 | J10: 3.376827 | K10: 3.379567 | L10: 62 | M10: Synthetic example
A11: 7 | B11: 47777 | D11: 2v2 skirmish (unrated, for weekly missions) | E11: W | F11: Emberguard-SandboxRealm (Buddy A, MM Hunter) | G11: Player0878-ExampleWorld034, Player0128-ExampleWorld164 | I11: 0 | J11: 2.379467 | K11: 2.127387 | L11: 26 | M11: Synthetic example
A12: 8 | B12: 47777 | D12: 2v2 rated | E12: L | F12: Thornpaw-SandboxRealm (Buddy B, Player0724 Priest, New) | G12: Player0404-ExampleWorld139, Player0829-ExampleWorld164 (healer by stats) | I12: 0 | J12: 4.746827 | K12: 1.475267 | L12: 0 | M12: Synthetic example
A13: 9 | B13: 47777 | D13: 2v2 rated | E13: L | F13: Thornpaw-SandboxRealm (Buddy B, Player0724 Priest, New) | G13: Player0895-ExampleWorld102, Player0626-SandboxRealm (no healer by stats) | I13: 4 | J13: 4.746827 | K13: 3.927567 | L13: 0 | M13: Synthetic example
A14: 10 | B14: 47777 | D14: 2v2 skirmish (unrated, for weekly missions) | E14: L | F14: Thornpaw-SandboxRealm (Buddy B, Player0724 Priest, New) | G14: Player0013-ExampleWorld091, Player0876-PracticeRealm (both DPS by stats) | I14: 0 | J14: 3.102827 | K14: 3.927567 | L14: 0 | M14: Synthetic example
A15: 11 | B15: 47777 | D15: 2v2 rated | E15: L | F15: Thornpaw-SandboxRealm (Buddy B, Player0724 Priest, New) | G15: Player0181-ExampleWorld133, Player0947-SandboxRealm (no healer by stats) | I15: 0 | J15: 3.924827 | K15: 4.201567 | L15: 0 | M15: Synthetic example
A16: 12 | B16: 47777 | C16: Ashamane's Fall | D16: 2v2 skirmish (unrated, for weekly missions) | E16: W | F16: Player0057-ExampleWorld196 (pug, Unholy Death Knight) | G16: Playerë0649-ExampleWorld091 (BM Hunter), Player0857-ExampleWorld179 (Ret Paladin) | H16: 1:16 | I16: 0 | J16: 1.620487 | K16: 2.831567 | L16: 26 | M16: Synthetic example
A17: 13 | B17: 47777 | C17: Black Rook Hold Arena | D17: 2v2 (rated or skirmish: unverified) | E17: W | F17: Emberguard-SandboxRealm (Buddy A, MM Hunter) | G17: Player0841-ExampleWorld021 (Frost Mage), Player0300-ExampleWorld021 (MM Hunter) | H17: 0:33 | I17: 4 | J17: 2.489067 | K17: 2.916507 | M17: Synthetic example
A19: Record | B19: =COUNTIF(E5:E500,"W")&"-"&COUNTIF(E5:E500,"L")

Sheet GM Summary
A1: Mossweaver — Summary
A2: All values calculate from the GM Battlegrounds tab.
A3: Stat | B3: Value
A4: Games | B4: =COUNTA('GM Battlegrounds'!$D$5:$D$1000)
A5: Wins | B5: =COUNTIF('GM Battlegrounds'!$G$5:$G$1000,"W")
A6: Losses | B6: =COUNTIF('GM Battlegrounds'!$G$5:$G$1000,"L")
A7: Win rate | B7: =IF(B4=0,0,B5/B4)
A8: Total healing (M) | B8: =SUM('GM Battlegrounds'!$O$5:$O$1000)
A9: Avg healing per game (M) | B9: =AVERAGE('GM Battlegrounds'!$O$5:$O$1000)
A10: Healing per minute (M) | B10: =SUM('GM Battlegrounds'!$O$5:$O$1000)/(SUM('GM Battlegrounds'!$F$5:$F$1000)*1440)
A11: Best healing (M) | B11: =MAX('GM Battlegrounds'!$O$5:$O$1000)
A12: Total player0354 kills | B12: =SUM('GM Battlegrounds'!$L$5:$L$1000)
A13: Avg player0354 kills | B13: =AVERAGE('GM Battlegrounds'!$L$5:$L$1000)
A14: Total killing blows | B14: =SUM('GM Battlegrounds'!$K$5:$K$1000)
A15: Games with deaths tracked | B15: =COUNT('GM Battlegrounds'!$M$5:$M$1000)
A16: Avg deaths (tracked) | B16: =IF(B15=0,"",AVERAGE('GM Battlegrounds'!$M$5:$M$1000))
A17: Zero-death games (tracked) | B17: =COUNTIF('GM Battlegrounds'!$M$5:$M$1000,0)
A18: Avg healing vs next Horde healer | B18: =IFERROR(AVERAGE('GM Battlegrounds'!$V$5:$V$1000),"")
A19: Rated games | B19: =COUNTIF('GM Battlegrounds'!$H$5:$H$1000,"Yes")
A20: Total honor | B20: =SUM('GM Battlegrounds'!$Q$5:$Q$1000)
A23: By map type
A24: Map type | B24: Games | C24: Wins | D24: Win rate | E24: Avg healing (M) | F24: Healing / min (M) | G24: Avg HKs
A25: Bases | B25: =COUNTIF('GM Battlegrounds'!$E$5:$E$1000,A25) | C25: =COUNTIFS('GM Battlegrounds'!$E$5:$E$1000,A25,'GM Battlegrounds'!$G$5:$G$1000,"W") | D25: =IF(B25=0,"",C25/B25) | E25: =IF(B25=0,"",SUMIFS('GM Battlegrounds'!$O$5:$O$1000,'GM Battlegrounds'!$E$5:$E$1000,A25)/B25) | F25: =IFERROR(IF(B25=0,"",SUMIFS('GM Battlegrounds'!$O$5:$O$1000,'GM Battlegrounds'!$E$5:$E$1000,A25)/(SUMIFS('GM Battlegrounds'!$F$5:$F$1000,'GM Battlegrounds'!$E$5:$E$1000,A25)*1440)),"") | G25: =IF(B25=0,"",SUMIFS('GM Battlegrounds'!$L$5:$L$1000,'GM Battlegrounds'!$E$5:$E$1000,A25)/B25)
A26: Flag | B26: =COUNTIF('GM Battlegrounds'!$E$5:$E$1000,A26) | C26: =COUNTIFS('GM Battlegrounds'!$E$5:$E$1000,A26,'GM Battlegrounds'!$G$5:$G$1000,"W") | D26: =IF(B26=0,"",C26/B26) | E26: =IF(B26=0,"",SUMIFS('GM Battlegrounds'!$O$5:$O$1000,'GM Battlegrounds'!$E$5:$E$1000,A26)/B26) | F26: =IFERROR(IF(B26=0,"",SUMIFS('GM Battlegrounds'!$O$5:$O$1000,'GM Battlegrounds'!$E$5:$E$1000,A26)/(SUMIFS('GM Battlegrounds'!$F$5:$F$1000,'GM Battlegrounds'!$E$5:$E$1000,A26)*1440)),"") | G26: =IF(B26=0,"",SUMIFS('GM Battlegrounds'!$L$5:$L$1000,'GM Battlegrounds'!$E$5:$E$1000,A26)/B26)
A27: Flag + Bases | B27: =COUNTIF('GM Battlegrounds'!$E$5:$E$1000,A27) | C27: =COUNTIFS('GM Battlegrounds'!$E$5:$E$1000,A27,'GM Battlegrounds'!$G$5:$G$1000,"W") | D27: =IF(B27=0,"",C27/B27) | E27: =IF(B27=0,"",SUMIFS('GM Battlegrounds'!$O$5:$O$1000,'GM Battlegrounds'!$E$5:$E$1000,A27)/B27) | F27: =IFERROR(IF(B27=0,"",SUMIFS('GM Battlegrounds'!$O$5:$O$1000,'GM Battlegrounds'!$E$5:$E$1000,A27)/(SUMIFS('GM Battlegrounds'!$F$5:$F$1000,'GM Battlegrounds'!$E$5:$E$1000,A27)*1440)),"") | G27: =IF(B27=0,"",SUMIFS('GM Battlegrounds'!$L$5:$L$1000,'GM Battlegrounds'!$E$5:$E$1000,A27)/B27)
A28: Orbs | B28: =COUNTIF('GM Battlegrounds'!$E$5:$E$1000,A28) | C28: =COUNTIFS('GM Battlegrounds'!$E$5:$E$1000,A28,'GM Battlegrounds'!$G$5:$G$1000,"W") | D28: =IF(B28=0,"",C28/B28) | E28: =IF(B28=0,"",SUMIFS('GM Battlegrounds'!$O$5:$O$1000,'GM Battlegrounds'!$E$5:$E$1000,A28)/B28) | F28: =IFERROR(IF(B28=0,"",SUMIFS('GM Battlegrounds'!$O$5:$O$1000,'GM Battlegrounds'!$E$5:$E$1000,A28)/(SUMIFS('GM Battlegrounds'!$F$5:$F$1000,'GM Battlegrounds'!$E$5:$E$1000,A28)*1440)),"") | G28: =IF(B28=0,"",SUMIFS('GM Battlegrounds'!$L$5:$L$1000,'GM Battlegrounds'!$E$5:$E$1000,A28)/B28)
A29: Carts | B29: =COUNTIF('GM Battlegrounds'!$E$5:$E$1000,A29) | C29: =COUNTIFS('GM Battlegrounds'!$E$5:$E$1000,A29,'GM Battlegrounds'!$G$5:$G$1000,"W") | D29: =IF(B29=0,"",C29/B29) | E29: =IF(B29=0,"",SUMIFS('GM Battlegrounds'!$O$5:$O$1000,'GM Battlegrounds'!$E$5:$E$1000,A29)/B29) | F29: =IFERROR(IF(B29=0,"",SUMIFS('GM Battlegrounds'!$O$5:$O$1000,'GM Battlegrounds'!$E$5:$E$1000,A29)/(SUMIFS('GM Battlegrounds'!$F$5:$F$1000,'GM Battlegrounds'!$E$5:$E$1000,A29)*1440)),"") | G29: =IF(B29=0,"",SUMIFS('GM Battlegrounds'!$L$5:$L$1000,'GM Battlegrounds'!$E$5:$E$1000,A29)/B29)
A30: Epic | B30: =COUNTIF('GM Battlegrounds'!$E$5:$E$1000,A30) | C30: =COUNTIFS('GM Battlegrounds'!$E$5:$E$1000,A30,'GM Battlegrounds'!$G$5:$G$1000,"W") | D30: =IF(B30=0,"",C30/B30) | E30: =IF(B30=0,"",SUMIFS('GM Battlegrounds'!$O$5:$O$1000,'GM Battlegrounds'!$E$5:$E$1000,A30)/B30) | F30: =IFERROR(IF(B30=0,"",SUMIFS('GM Battlegrounds'!$O$5:$O$1000,'GM Battlegrounds'!$E$5:$E$1000,A30)/(SUMIFS('GM Battlegrounds'!$F$5:$F$1000,'GM Battlegrounds'!$E$5:$E$1000,A30)*1440)),"") | G30: =IF(B30=0,"",SUMIFS('GM Battlegrounds'!$L$5:$L$1000,'GM Battlegrounds'!$E$5:$E$1000,A30)/B30)
A32: Season ratings (Midnight Season 2, from the PvP panel)
A33: Bracket | B33: Current rating | C33: Season best | D33: Won | E33: Played | F33: Win rate
A34: Solo Shuffle (rounds) | B34: 1243 | C34: 1303 | D34: 47 | E34: 118 | F34: =IF(E34=0,"",D34/E34)
A35: Solo BG Blitz | B35: 860 | C35: 860 | D35: 3 | E35: 22 | F35: =IF(E35=0,"",D35/E35)
A36: 2v2 | B36: 479 | C36: 479 | D36: 5 | E36: 10 | F36: =IF(E36=0,"",D36/E36)
A37: 3v3 | B37: 1148 | C37: 1148 | D37: 12 | E37: 33 | F37: =IF(E37=0,"",D37/E37)
A38: 10v10 Rated BG | B38: 0 | C38: 0 | D38: 0 | E38: 0 | F38: =IF(E38=0,"",D38/E38)
A40: Snapshot from 10/20/2026; 2v2 updated 10/21 from a scoreboard (+95 win). Update when you check the PvP panel. Shuffle counts rounds, not lobbies.

Sheet GM Battlegrounds
A1: Mossweaver — Battleground Match Log
A2: Blue = entered data · Black = formulas · Green rows = wins, red rows = losses.
A4: Game # | B4: Date | C4: Time | D4: Battleground | E4: Map type | F4: Duration | G4: Result | H4: Rated? | I4: Our score | J4: Enemy score | K4: KB | L4: HK | M4: Deaths | N4: Damage (M) | O4: Healing (M) | P4: Healing / min (M) | Q4: Honor | R4: Conquest | S4: Role | T4: Healing rank | U4: Next Horde healer (M) | V4: Healing vs next healer | W4: Bases assaulted | X4: Flag captures | Y4: Carts controlled | Z4: Data source | AA4: Notes | AB4: PvP item level | AC4: Horde deaths | AD4: Alliance deaths | AE4: Healers (Horde vs Alliance) | AF4: Horde healing (M) | AG4: Alliance healing (M) | AH4: Premade on mains? | AI4: Teammates on mains
A5: 1 | B5: 47759 | C5: 05:05 PM | D5: Deephaul Ravine | E5: Carts | F5: 0.0058912037 | G5: L | K5: 4 | L5: 0 | N5: 3.952227 | O5: 65.659767 | P5: =IF(OR(F5="",F5=0),"",O5/(F5*1440)) | Q5: 177 | V5: =IF(U5="","",O5/U5) | Z5: REFlex
A6: 2 | B6: 47759 | C6: 05:25 PM | D6: Eye of the Storm | E6: Flag + Bases | F6: 0.0076736111 | G6: L | I6: 656 | J6: 1517 | K6: 0 | L6: 3 | M6: 10 | N6: 5.623627 | O6: 50.699367 | P6: =IF(OR(F6="",F6=0),"",O6/(F6*1440)) | Q6: 289 | S6: Healer | U6: 36 | V6: =IF(U6="","",O6/U6) | Z6: REFlex + scoreboard | AA6: Synthetic example | AH6: Yes | AI6: 2 of 3 (raid frames + visible roster)
A7: 3 | B7: 47759 | C7: 05:40 PM | D7: Deephaul Ravine | E7: Carts | F7: 0.0054166667 | G7: W | I7: 1517 | J7: 617 | K7: 0 | L7: 2 | M7: 0 | N7: 5.541427 | O7: 63.193767 | P7: =IF(OR(F7="",F7=0),"",O7/(F7*1440)) | Q7: 528 | S7: Healer / cart escort | U7: 55 | V7: =IF(U7="","",O7/U7) | Y7: 20 | Z7: REFlex + scoreboard | AA7: Synthetic example | AH7: Unknown | AI7: 1 of 3 (visible; Buddy D's status decides)
A8: 4 | B8: 47759 | C8: 05:55 PM | D8: Silvershard Mines | E8: Carts | F8: 0.0048611111 | G8: W | I8: 1517 | J8: 358 | K8: 7 | L8: 10 | M8: 0 | N8: 7.843027 | O8: 98.265767 | P8: =IF(OR(F8="",F8=0),"",O8/(F8*1440)) | Q8: 571 | S8: Healer | T8: 1st overall | U8: 33 | V8: =IF(U8="","",O8/U8) | Y8: 20 | Z8: REFlex + scoreboard | AA8: Synthetic example | AH8: Yes | AI8: 2 of 3 (raid frames + visible roster)
A9: 5 | B9: 47759 | C9: 06:12 PM | D9: Warsong Gulch | E9: Flag | F9: 0.0053587963 | G9: W | I9: 20 | J9: 0 | K9: 4 | L9: 0 | M9: 0 | N9: 6.664827 | O9: 45.383767 | P9: =IF(OR(F9="",F9=0),"",O9/(F9*1440)) | Q9: 699 | S9: Healer / FC escort | T9: 4th of 20 | U9: 39 | V9: =IF(U9="","",O9/U9) | X9: 0 | Z9: REFlex + scoreboard | AA9: Synthetic example | AH9: Yes | AI9: 2 of 4 (raid frames)
A10: 6 | B10: 47759 | C10: 06:25 PM | D10: Deephaul Ravine | E10: Carts | F10: 0.0045601852 | G10: W | I10: 1517 | J10: 489 | K10: 0 | L10: 4 | M10: 0 | N10: 8.254027 | O10: 70.125967 | P10: =IF(OR(F10="",F10=0),"",O10/(F10*1440)) | Q10: 533 | S10: Healer | U10: 43 | V10: =IF(U10="","",O10/U10) | Z10: REFlex + scoreboard | AA10: Synthetic example | AH10: Yes | AI10: 2 of 3 (raid frames + visible roster)
A11: 7 | B11: 47759 | C11: 06:45 PM | D11: Arathi Basin | E11: Bases | F11: 0.0073032407 | G11: W | K11: 0 | L11: 8 | N11: 4.856427 | O11: 53.411967 | P11: =IF(OR(F11="",F11=0),"",O11/(F11*1440)) | Q11: 672 | V11: =IF(U11="","",O11/U11) | Z11: REFlex
A12: 8 | B12: 47759 | C12: 06:58 PM | D12: Eye of the Storm | E12: Flag + Bases | F12: 0.0034837963 | G12: W | K12: 0 | L12: 2 | N12: 0.617647 | O12: 9.188367 | P12: =IF(OR(F12="",F12=0),"",O12/(F12*1440)) | Q12: 623 | V12: =IF(U12="","",O12/U12) | Z12: REFlex
A13: 9 | B13: 47759 | C13: 07:10 PM | D13: Temple of Kotmogu | E13: Orbs | F13: 0.0046296296 | G13: W | K13: 0 | L13: 1 | N13: 1.924627 | O13: 58.261767 | P13: =IF(OR(F13="",F13=0),"",O13/(F13*1440)) | Q13: 580 | V13: =IF(U13="","",O13/U13) | Z13: REFlex
A14: 10 | B14: 47759 | C14: 07:29 PM | D14: Temple of Kotmogu | E14: Orbs | F14: 0.0070601852 | G14: L | K14: 0 | L14: 10 | N14: 17.378227 | O14: 127.69337 | P14: =IF(OR(F14="",F14=0),"",O14/(F14*1440)) | Q14: 337 | V14: =IF(U14="","",O14/U14) | Z14: REFlex
A15: 11 | B15: 47759 | C15: 07:53 PM | D15: Silvershard Mines | E15: Carts | F15: 0.0056134259 | G15: W | K15: 0 | L15: 3 | N15: 3.513827 | O15: 40.259967 | P15: =IF(OR(F15="",F15=0),"",O15/(F15*1440)) | Q15: 579 | V15: =IF(U15="","",O15/U15) | Z15: REFlex
A16: 12 | B16: 47759 | C16: 08:09 PM | D16: Eye of the Storm | E16: Flag + Bases | F16: 0.0055671296 | G16: W | K16: 4 | L16: 0 | N16: 5.240027 | O16: 67.413367 | P16: =IF(OR(F16="",F16=0),"",O16/(F16*1440)) | Q16: 808 | V16: =IF(U16="","",O16/U16) | Z16: REFlex
A17: 13 | B17: 47759 | C17: 08:28 PM | D17: Temple of Kotmogu | E17: Orbs | F17: 0.0049652778 | G17: L | K17: 0 | L17: 1 | N17: 13.323027 | O17: 71.934367 | P17: =IF(OR(F17="",F17=0),"",O17/(F17*1440)) | Q17: 256 | V17: =IF(U17="","",O17/U17) | Z17: REFlex
A18: 14 | B18: 47760 | C18: 10:28 AM | D18: Eye of the Storm | E18: Flag + Bases | F18: 0.005462963 | G18: W | K18: 4 | L18: 10 | N18: 5.020827 | O18: 44.095967 | P18: =IF(OR(F18="",F18=0),"",O18/(F18*1440)) | Q18: 870 | V18: =IF(U18="","",O18/U18) | Z18: REFlex
A19: 15 | B19: 47760 | C19: 10:39 AM | D19: Temple of Kotmogu | E19: Orbs | F19: 0.0047916667 | G19: L | K19: 0 | L19: 0 | N19: 2.135607 | O19: 42.917767 | P19: =IF(OR(F19="",F19=0),"",O19/(F19*1440)) | Q19: 249 | V19: =IF(U19="","",O19/U19) | Z19: REFlex | AA19: Synthetic example
A20: 16 | B20: 47760 | C20: 10:56 AM | D20: Warsong Gulch | E20: Flag | F20: 0.010416667 | G20: L | K20: 0 | L20: 1 | N20: 19.049627 | O20: 147.64057 | P20: =IF(OR(F20="",F20=0),"",O20/(F20*1440)) | Q20: 402 | V20: =IF(U20="","",O20/U20) | Z20: REFlex
A21: 17 | B21: 47760 | C21: 11:35 AM | D21: Deepwind Gorge | E21: Bases | F21: 0.011759259 | G21: W | K21: 4 | L21: 6 | N21: 7.130627 | O21: 110.23957 | P21: =IF(OR(F21="",F21=0),"",O21/(F21*1440)) | Q21: 629 | V21: =IF(U21="","",O21/U21) | Z21: REFlex
A22: 18 | B22: 47760 | C22: 11:48 AM | D22: Temple of Kotmogu | E22: Orbs | F22: 0.0039814815 | G22: L | K22: 0 | L22: 8 | N22: 5.568827 | O22: 41.383367 | P22: =IF(OR(F22="",F22=0),"",O22/(F22*1440)) | Q22: 189 | V22: =IF(U22="","",O22/U22) | Z22: REFlex
A23: 19 | B23: 47760 | C23: 12:11 PM | D23: Arathi Basin | E23: Bases | F23: 0.0091898148 | G23: L | K23: 0 | L23: 7 | N23: 9.980227 | O23: 96.840967 | P23: =IF(OR(F23="",F23=0),"",O23/(F23*1440)) | Q23: 418 | V23: =IF(U23="","",O23/U23) | Z23: REFlex
A24: 20 | B24: 47760 | C24: 12:48 PM | D24: Twin Peaks | E24: Flag | F24: 0.010358796 | G24: L | K24: 0 | L24: 7 | N24: 4.034427 | O24: 57.713767 | P24: =IF(OR(F24="",F24=0),"",O24/(F24*1440)) | Q24: 433 | V24: =IF(U24="","",O24/U24) | Z24: REFlex
A25: 21 | B25: 47762 | C25: 05:22 PM | D25: Arathi Basin | E25: Bases | F25: 0.010891204 | G25: W | K25: 0 | L25: 2 | N25: 16.556227 | O25: 91.771967 | P25: =IF(OR(F25="",F25=0),"",O25/(F25*1440)) | Q25: 947 | V25: =IF(U25="","",O25/U25) | Z25: REFlex | AA25: Synthetic example
A26: 22 | B26: 47762 | C26: 05:47 PM | D26: Arathi Basin | E26: Bases | F26: 0.0085532407 | G26: L | K26: 0 | L26: 4 | N26: 6.856627 | O26: 36.560967 | P26: =IF(OR(F26="",F26=0),"",O26/(F26*1440)) | Q26: 430 | V26: =IF(U26="","",O26/U26) | Z26: REFlex | AA26: Synthetic example
A27: 23 | B27: 47762 | C27: 06:12 PM | D27: Arathi Basin | E27: Bases | F27: 0.011724537 | G27: L | K27: 0 | L27: 5 | N27: 13.377827 | O27: 122.18597 | P27: =IF(OR(F27="",F27=0),"",O27/(F27*1440)) | Q27: 561 | V27: =IF(U27="","",O27/U27) | Z27: REFlex | AA27: Synthetic example
A28: 24 | B28: 47762 | C28: 06:17 PM | D28: The Battle for Gilneas | E28: Bases | F28: 0.0017939815 | G28: W | K28: 0 | L28: 2 | N28: 3.157627 | O28: 24.888567 | P28: =IF(OR(F28="",F28=0),"",O28/(F28*1440)) | Q28: 843 | V28: =IF(U28="","",O28/U28) | Z28: REFlex
A29: 25 | B29: 47762 | C29: 06:30 PM | D29: Deephaul Ravine | E29: Carts | F29: 0.0043171296 | G29: W | K29: 4 | L29: 4 | N29: 2.119167 | O29: 52.096767 | P29: =IF(OR(F29="",F29=0),"",O29/(F29*1440)) | Q29: 515 | V29: =IF(U29="","",O29/U29) | Z29: REFlex
A30: 26 | B30: 47763 | C30: 06:11 PM | D30: Temple of Kotmogu | E30: Orbs | F30: 0.0061805556 | G30: W | K30: 4 | L30: 7 | N30: 8.473227 | O30: 93.799567 | P30: =IF(OR(F30="",F30=0),"",O30/(F30*1440)) | Q30: 856 | V30: =IF(U30="","",O30/U30) | Z30: REFlex
A31: 27 | B31: 47763 | C31: 06:29 PM | D31: Arathi Basin | E31: Bases | F31: 0.010011574 | G31: L | K31: 0 | L31: 9 | N31: 4.719427 | O31: 43.410967 | P31: =IF(OR(F31="",F31=0),"",O31/(F31*1440)) | Q31: 492 | V31: =IF(U31="","",O31/U31) | Z31: REFlex | AA31: Synthetic example
A32: 28 | B32: 47764 | C32: 07:13 PM | D32: Warsong Gulch | E32: Flag | F32: 0.004224537 | G32: W | K32: 4 | L32: 5 | N32: 4.308427 | O32: 20.970367 | P32: =IF(OR(F32="",F32=0),"",O32/(F32*1440)) | Q32: 940 | V32: =IF(U32="","",O32/U32) | Z32: REFlex
A33: 29 | B33: 47767 | C33: 03:44 PM | D33: Temple of Kotmogu | E33: Orbs | F33: 0.0020717593 | G33: L | H33: Yes | K33: 0 | L33: 0 | N33: 0.214867 | O33: 23.134967 | P33: =IF(OR(F33="",F33=0),"",O33/(F33*1440)) | Q33: 122 | V33: =IF(U33="","",O33/U33) | Z33: REFlex | AA33: Synthetic example
A34: 30 | B34: 47767 | C34: 05:08 PM | D34: Twin Peaks | E34: Flag | F34: 0.010046296 | G34: L | K34: 0 | L34: 6 | N34: 0.409407 | O34: 95.306567 | P34: =IF(OR(F34="",F34=0),"",O34/(F34*1440)) | Q34: 419 | V34: =IF(U34="","",O34/U34) | Z34: REFlex
A35: 31 | B35: 47767 | C35: 05:28 PM | D35: Silvershard Mines | E35: Carts | F35: 0.0060185185 | G35: W | K35: 0 | L35: 9 | N35: 2.050667 | O35: 28.614967 | P35: =IF(OR(F35="",F35=0),"",O35/(F35*1440)) | Q35: 771 | V35: =IF(U35="","",O35/U35) | Z35: REFlex
A36: 32 | B36: 47767 | C36: 06:20 PM | D36: Arathi Basin | E36: Bases | F36: 0.011678241 | G36: W | K36: 4 | L36: 2 | N36: 3.185027 | O36: 88.977167 | P36: =IF(OR(F36="",F36=0),"",O36/(F36*1440)) | Q36: 715 | V36: =IF(U36="","",O36/U36) | Z36: REFlex
A37: 33 | B37: 47767 | C37: 06:38 PM | D37: Eye of the Storm | E37: Flag + Bases | F37: 0.0067592593 | G37: W | K37: 0 | L37: 0 | N37: 1.151947 | O37: 9.215767 | P37: =IF(OR(F37="",F37=0),"",O37/(F37*1440)) | Q37: 788 | V37: =IF(U37="","",O37/U37) | Z37: REFlex
A38: 34 | B38: 47767 | C38: 06:51 PM | D38: Deephaul Ravine | E38: Carts | F38: 0.0058217593 | G38: L | K38: 0 | L38: 5 | N38: 0.497087 | O38: 72.701567 | P38: =IF(OR(F38="",F38=0),"",O38/(F38*1440)) | Q38: 206 | V38: =IF(U38="","",O38/U38) | Z38: REFlex
A39: 35 | B39: 47770 | C39: 04:56 PM | D39: Eye of the Storm | E39: Flag + Bases | F39: 0.0087615741 | G39: W | I39: 1517 | J39: 1213 | K39: 4 | L39: 4 | N39: 1.384847 | O39: 61.988167 | P39: =IF(OR(F39="",F39=0),"",O39/(F39*1440)) | Q39: 1427 | R39: 65 | S39: Healer | T39: 2nd of 30 | U39: 56 | V39: =IF(U39="","",O39/U39) | Z39: REFlex + scoreboard | AA39: Synthetic example | AH39: Yes | AI39: 2 of 2 (visible roster)
A40: 36 | B40: 47770 | C40: 05:11 PM | D40: Silvershard Mines | E40: Carts | F40: 0.0060763889 | G40: L | I40: 850 | J40: 1517 | K40: 0 | L40: 7 | M40: 0 | N40: 1.527327 | O40: 61.083967 | P40: =IF(OR(F40="",F40=0),"",O40/(F40*1440)) | Q40: 439 | S40: Healer / cart escort | T40: 3rd overall | V40: =IF(U40="","",O40/U40) | Y40: 18 | Z40: REFlex + scoreboard | AA40: Synthetic example
A41: 37 | B41: 47770 | C41: 05:22 PM | D41: Eye of the Storm | E41: Flag + Bases | F41: 0.0045486111 | G41: L | H41: Yes | I41: 563 | J41: 1517 | K41: 0 | L41: 5 | M41: 7 | N41: 1.020427 | O41: 53.740767 | P41: =IF(OR(F41="",F41=0),"",O41/(F41*1440)) | Q41: 230 | R41: 47 | S41: Healer (duo with Buddy B) | T41: 1st of 16 | U41: 33 | V41: =IF(U41="","",O41/U41) | Z41: REFlex + scoreboard | AA41: Synthetic example | AH41: No | AI41: 1 of 1 (full Blitz roster)
...

Sheet GM Arena
A1: Mossweaver — Arena Log
A2: From REFlex unless noted (games 28-31 from scoreboards). Bracket inferred from team size and rating column. 4 older rows were not visible in the screenshots.
A4: # | B4: Date | C4: Time | D4: Arena | E4: Bracket | F4: Result | G4: Shuffle rounds | H4: Team MMR | I4: Enemy MMR | J4: Duration | K4: Damage (M) | L4: Healing (M) | M4: Rating change | N4: Notes
A5: 1 | B5: 47760 | C5: 10:17 AM | D5: TR | E5: 3v3 skirmish | F5: W | J5: 0.0016898148 | K5: 1.716387 | L5: 13.873767
A6: 2 | B6: 47764 | C6: 06:54 PM | D6: CoC | E6: 3v3 | F6: W | H6: 1814 | I6: 1798 | J6: 0 | K6: 0 | L6: 0 | M6: 113 | N6: Synthetic example
